<robot
  name="my_robot">
<!-- Space btw top of beam and the each joint -->
  <material name="black">
    <color rgba="0.0 0.0 0.0 1.0"/>
  </material>
  <material name="blue">
    <color rgba="0.0 0.0 0.8 1.0"/>
  </material>
  <material name="green">
    <color rgba="0.0 0.8 0.0 1.0"/>
  </material>
  <material name="grey">
    <color rgba="0.2 0.2 0.2 1.0"/>
  </material>
  <material name="orange">
    <color rgba="1.0 0.423529411765 0.0392156862745 1.0"/>
  </material>
  <material name="brown">
    <color rgba="0.870588235294 0.811764705882 0.764705882353 1.0"/>
  </material>
  <material name="red">
    <color rgba="0.8 0.0 0.0 1.0"/>
  </material>
  <material name="white">
    <color rgba="1.0 1.0 1.0 1.0"/>
  </material>

  <link
    name="BASE_LINK">
    
    <visual>
      <origin
        xyz="0 0 0"
        rpy="0 0 0" />
      <geometry>
        <mesh
          filename="package://my_robot/meshes/BASE_LINK.STL" />
      </geometry>
      <material
        name="red"/>
    </visual>
    <collision>
      <origin
        xyz="0 0 0"
        rpy="0 0 0" />
      <geometry>
        <mesh
          filename="package://my_robot/meshes/BASE_LINK.STL" />
      </geometry>
    </collision>
    <inertial>
      <origin rpy="0 0 0" xyz="0 0 1"/>
      <mass value="1"/>
      <inertia ixx="1.0" ixy="0.0" ixz="0.0" iyy="1.0" iyz="0.0" izz="1.0"/>
    </inertial>
  </link>
  <link
    name="LINK1">
   
    <visual>
      <origin
        xyz="0 0 0"
        rpy="0 0 0" />
      <geometry>
        <mesh
          filename="package://my_robot/meshes/LINK1.STL" />
      </geometry>
      <material
        name="blue"/>
       
    </visual>
    <collision>
      <origin
        xyz="0 0 0"
        rpy="0 0 0" />
      <geometry>
        <mesh
          filename="package://my_robot/meshes/LINK1.STL" />
      </geometry>
    </collision>
    <inertial>
      <origin rpy="0 0 0" xyz="0 0 1"/>
      <mass value="1"/>
      <inertia ixx="1.0" ixy="0.0" ixz="0.0" iyy="1.0" iyz="0.0" izz="1.0"/>
    </inertial>
  </link>
  <joint
    name="JOINT1"
    type="continuous">
    <origin
      xyz="-0.0078513 -0.1185 -0.0085599"
      rpy="1.5708 0 0" />
    <parent
      link="BASE_LINK" />
    <child
      link="LINK1" />
    <axis
      xyz="0 0 1" />
  </joint>
  <link
    name="LINK2">
   
    <visual>
      <origin
        xyz="0 0 0"
        rpy="0 0 0" />
      <geometry>
        <mesh
          filename="package://my_robot/meshes/LINK2.STL" />
      </geometry>
      <material
        name="red"/>
       
    </visual>
    <collision>
      <origin
        xyz="0 0 0"
        rpy="0 0 0" />
      <geometry>
        <mesh
          filename="package://my_robot/meshes/LINK2.STL" />
      </geometry>
    </collision>
    <inertial>
      <origin rpy="0 0 0" xyz="0 0 1"/>
      <mass value="1"/>
      <inertia ixx="1.0" ixy="0.0" ixz="0.0" iyy="1.0" iyz="0.0" izz="1.0"/>
    </inertial>
  </link>
  <joint
    name="JOINT2"
    type="continuous">
    <origin
      xyz="0 0 0.074001715387442"
      rpy="-1.57079632679491 -0.113608660055019 -1.53921879739516" />
    <parent
      link="LINK1" />
    <child
      link="LINK2" />
    <axis
      xyz="0 0 1" />
  </joint>
  <link
    name="LINK3">
   
    <visual>
      <origin
        xyz="0 0 0"
        rpy="0 0 0" />
      <geometry>
        <mesh
          filename="package://my_robot/meshes/LINK3.STL" />
      </geometry>
      <material
        name="blue"/>
       
    </visual>
    <collision>
      <origin
        xyz="0 0 0"
        rpy="0 0 0" />
      <geometry>
        <mesh
          filename="package://my_robot/meshes/LINK3.STL" />
      </geometry>
    </collision>
    <inertial>
      <origin rpy="0 0 0" xyz="0 0 1"/>
      <mass value="1"/>
      <inertia ixx="1.0" ixy="0.0" ixz="0.0" iyy="1.0" iyz="0.0" izz="1.0"/>
    </inertial>
  </link>
  <joint
    name="JOINT3"
    type="continuous">
    <origin
      xyz="0.0581638306158848 0 0.00849999999998774"
      rpy="0 1.5707963267949 0" />
    <parent
      link="LINK2" />
    <child
      link="LINK3" />
    <axis
      xyz="0 0 -1" />
  </joint>
  <link
    name="LINK4">
   
    <visual>
      <origin
        xyz="0 0 0"
        rpy="0 0 0" />
      <geometry>
        <mesh
          filename="package://my_robot/meshes/LINK4.STL" />
      </geometry>
      <material
        name="red"/>
        
    </visual>
    <collision>
      <origin
        xyz="0 0 0"
        rpy="0 0 0" />
      <geometry>
        <mesh
          filename="package://my_robot/meshes/LINK4.STL" />
      </geometry>
    </collision>
    <inertial>
      <origin rpy="0 0 0" xyz="0 0 1"/>
      <mass value="1"/>
      <inertia ixx="1.0" ixy="0.0" ixz="0.0" iyy="1.0" iyz="0.0" izz="1.0"/>
    </inertial>
  </link>
  <joint
    name="JOINT4"
    type="continuous">
    <origin
      xyz="0 0 0.200336169384111"
      rpy="0.00844604854241078 1.5707963267949 3.14159265358" />
    <parent
      link="LINK3" />
    <child
      link="LINK4" />
    <axis
      xyz="0 0 1" />
  </joint>
  <link
    name="LINK5">
   
    <visual>
      <origin
        xyz="0 0 0"
        rpy="0 0 0" />
      <geometry>
        <mesh
          filename="package://my_robot/meshes/LINK5.STL" />
      </geometry>
      <material
        name="blue"/>
        
    </visual>
    <collision>
      <origin
        xyz="0 0 0"
        rpy="0 0 0" />
      <geometry>
        <mesh
          filename="package://my_robot/meshes/LINK5.STL" />
      </geometry>
    </collision>
    <inertial>
      <origin rpy="0 0 0" xyz="0 0 1"/>
      <mass value="1"/>
      <inertia ixx="1.0" ixy="0.0" ixz="0.0" iyy="1.0" iyz="0.0" izz="1.0"/>
    </inertial>
  </link>
  <joint
    name="JOINT5"
    type="continuous">
    <origin
      xyz="-0.000139241080417352 0.00880880950278104 9.9999999999521E-05"
      rpy="-1.58660203641888 -1.5707963267949 0" />
    <parent
      link="LINK4" />
    <child
      link="LINK5" />
    <axis
      xyz="0 0 1" />
  </joint>
</robot>
